Workbook

Sheet Planilha1
A1: Data | B1: Débito | C1: Crédito | D1: Valor | F1: Histórico
A2: 01/04/2026 | B2: 1025 | C2: 9 | D2: -1.89 | F2: TAR/CUSTAS COBRANCA
A3: 01/04/2026 | B3: 1004 | C3: 9 | D3: -1648.58 | F3: BOLETO PAGO MENEGOTTI MA
A4: 01/04/2026 | B4: 1004 | C4: 9 | D4: -2747.61 | F4: BOLETO PAGO TRAPP FUNDO
A5: 01/04/2026 | B5: 1004 | C5: 9 | D5: -685.4 | F5: BOLETO PAGO MENEGOTTI MA
A6: 01/04/2026 | B6: 1004 | C6: 9 | D6: -395.27 | F6: BOLETO PAGO MENEGOTTI MA
A7: 01/04/2026 | B7: 1004 | C7: 9 | D7: -837.27 | F7: BOLETO PAGO NOVA CASA DI
A8: 01/04/2026 | B8: 1004 | C8: 9 | D8: -418.63 | F8: BOLETO PAGO CSM-COMPONEN
A9: 01/04/2026 | B9: 1004 | C9: 9 | D9: -514.44 | F9: BOLETO PAGO NOVA DIST DE
A10: 01/04/2026 | B10: 1004 | C10: 9 | D10: -4585.14 | F10: BOLETO PAGO BLACK E DECK
A11: 01/04/2026 | B11: 1004 | C11: 9 | D11: -1300.99 | F11: BOLETO PAGO ROBERT BOSCH
A12: 01/04/2026 | B12: 1004 | C12: 9 | D12: -191.72 | F12: BOLETO PAGO BLACK E DECK
A13: 01/04/2026 | B13: 1004 | C13: 9 | D13: -1132.32 | F13: BOLETO PAGO O V D IMP E
... A15: 01/04/2026 | B15: 1004 | C15: 9 | D15: -150 | F15: BOLETO PAGO SKYTEF
A16: 01/04/2026 | D16: 555 | F16: BOLETO RECEBIDO 01/04S
A17: 01/04/2026 | D17: 12069.39 | F17: RES APLIC AUT MAIS
A18: 01/04/2026 | D18: 207.73 | F18: RECEBIMENTO REDE MAST DB0096006021
A19: 01/04/2026 | D19: 347.28 | F19: RECEBIMENTO REDE VISA DB0096006021
A20: 01/04/2026 | D20: 0.02 | F20: RENDIMENTOS REND PAGO APLIC AUT MAIS
A21: 01/04/2026 | D21: 499.9 | F21: PIX QR CODE RECEBIDO RODRIGO COR01/04
A22: 01/04/2026 | D22: 1499.9 | F22: PIX QR CODE RECEBIDO USINOX ARTI01/04
A23: 01/04/2026 | D23: 96.3 | F23: PIX QR CODE RECEBIDO MARCOS ALBE01/04
A24: 01/04/2026 | D24: 365 | F24: PIX QR CODE RECEBIDO MARCOS ALBE01/04
A25: 02/04/2026 | B25: 1025 | C25: 9 | D25: -9.45 | F25: TAR/CUSTAS COBRANCA
A26: 02/04/2026 | D26: -43.32 | F26: TAR PIXQR LIQ MAQUININHA
A27: 02/04/2026 | D27: -290.9 | F27: TAR PIX QR CODE LIQUIDA
A28: 02/04/2026 | B28: 1004 | C28: 9 | D28: -528.63 | F28: BOLETO PAGO MENEGOTTI MA
A29: 02/04/2026 | B29: 1004 | C29: 9 | D29: -1212.2 | F29: BOLETO PAGO O V D IMP E
A30: 02/04/2026 | D30: -46.76 | F30: BOLETO PAGO MAKITA BR FE
A31: 02/04/2026 | D31: -1707.85 | F31: BOLETO PAGO LYNUS IND CO
A32: 02/04/2026 | D32: -3800 | F32: BOLETO PAGO EXITO CONTAB
A33: 02/04/2026 | D33: -3131.2 | F33: BOLETO PAGO FERRAMENTAS
A34: 02/04/2026 | B34: 1004 | C34: 9 | D34: -944.39 | F34: BOLETO PAGO BLACK E DECK
A35: 02/04/2026 | B35: 1004 | C35: 9 | D35: -1008.79 | F35: BOLETO PAGO O V D IMP E
A36: 02/04/2026 | D36: -1979.88 | F36: BOLETO PAGO KADESH EQUIP
A37: 02/04/2026 | B37: 1004 | C37: 9 | D37: -652.41 | F37: BOLETO PAGO MENEGOTTI MA
A38: 02/04/2026 | D38: -1464.04 | F38: BOLETO PAGO FERRAMENTAS
A39: 02/04/2026 | B39: 1004 | C39: 9 | D39: -1811.38 | F39: BOLETO PAGO TRAMONTINA P
A40: 02/04/2026 | D40: 1690.7 | F40: RECEBIMENTOS SDB COM DE ALIM L
A41: 02/04/2026 | D41: 2721.35 | F41: BOLETO RECEBIDO 02/04S
...

Sheet Planilha2
A2: BOLETO PAGO BLACK E DECK | B2: =IFERROR(INDEX(Planilha3!B:B,MATCH("*"&SUBSTITUTE(A2,"BOLETO PAGO ","")&"*",Planilha3!B:B,0)),"") -> BLACK E DECKER DO BRASIL LTDA
A3: BOLETO PAGO ROBERT BOSCH | B3: =IFERROR(INDEX(Planilha3!B:B,MATCH("*"&SUBSTITUTE(A3,"BOLETO PAGO ","")&"*",Planilha3!B:B,0)),"") -> ROBERT BOSCH LIMITADA
A4: BOLETO PAGO O V D IMP E | B4: =IFERROR(INDEX(Planilha3!B:B,MATCH("*"&SUBSTITUTE(A4,"BOLETO PAGO ","")&"*",Planilha3!B:B,0)),"")
A5: BOLETO PAGO SKYTEF | B5: =IFERROR(INDEX(Planilha3!B:B,MATCH("*"&SUBSTITUTE(A5,"BOLETO PAGO ","")&"*",Planilha3!B:B,0)),"")
A6: TAR PIXQR LIQ MAQUININHA | B6: =IFERROR(INDEX(Planilha3!B:B,MATCH("*"&SUBSTITUTE(A6,"BOLETO PAGO ","")&"*",Planilha3!B:B,0)),"")
A7: TAR PIX QR CODE LIQUIDA | B7: =IFERROR(INDEX(Planilha3!B:B,MATCH("*"&SUBSTITUTE(A7,"BOLETO PAGO ","")&"*",Planilha3!B:B,0)),"")
A8: BOLETO PAGO MAKITA BR FE | B8: =IFERROR(INDEX(Planilha3!B:B,MATCH("*"&SUBSTITUTE(A8,"BOLETO PAGO ","")&"*",Planilha3!B:B,0)),"")
A9: BOLETO PAGO LYNUS IND CO | B9: =IFERROR(INDEX(Planilha3!B:B,MATCH("*"&SUBSTITUTE(A9,"BOLETO PAGO ","")&"*",Planilha3!B:B,0)),"")
A10: BOLETO PAGO EXITO CONTAB | B10: =IFERROR(INDEX(Planilha3!B:B,MATCH("*"&SUBSTITUTE(A10,"BOLETO PAGO ","")&"*",Planilha3!B:B,0)),"")
A11: BOLETO PAGO FERRAMENTAS | B11: =IFERROR(INDEX(Planilha3!B:B,MATCH("*"&SUBSTITUTE(A11,"BOLETO PAGO ","")&"*",Planilha3!B:B,0)),"") -> GURGELMIX MAQUINAS E FERRAMENTAS S.A.
A12: BOLETO PAGO KADESH EQUIP | B12: =IFERROR(INDEX(Planilha3!B:B,MATCH("*"&SUBSTITUTE(A12,"BOLETO PAGO ","")&"*",Planilha3!B:B,0)),"")
A13: BOLETO PAGO TRAMONTINA P | B13: =IFERROR(INDEX(Planilha3!B:B,MATCH("*"&SUBSTITUTE(A13,"BOLETO PAGO ","")&"*",Planilha3!B:B,0)),"") -> TRAMONTINA PLANALTO S/A
... A81: BOLETO PAGO VCH IMPORTAD | B81: =IFERROR(INDEX(Planilha3!B:B,MATCH("*"&SUBSTITUTE(A81,"BOLETO PAGO ","")&"*",Planilha3!B:B,0)),"")

Sheet Planilha3
A1: FORNECEDORES | B1: BLACK E DECKER DO BRASIL LTDA
A2: FORNECEDORES | B2: BLACK E DECKER DO BRASIL LTDA
A3: FORNECEDORES | B3: CSM COMPONENTES SISTEMAS E MAQUINAS PARA CONSTRUCA
A4: FORNECEDORES | B4: GURGELMIX MAQUINAS E FERRAMENTAS S.A.
A5: FORNECEDORES | B5: HIDROMEPE ENG. MANUT.HIDR. IND. COM.LTDA
A6: FORNECEDORES | B6: MENEGOTTI INDUSTRIAS METALURGICAS LTDA EM RECUPER.
A7: FORNECEDORES | B7: MENEGOTTI INDUSTRIAS METALURGICAS LTDA EM RECUPER.
A8: FORNECEDORES | B8: MENEGOTTI INDUSTRIAS METALURGICAS LTDA EM RECUPER.
A9: FORNECEDORES | B9: METALURGICA TRAPP LTDA
A10: FORNECEDORES | B10: MULTIVAREJO ES LTDA
A11: FORNECEDORES | B11: NOVA CASA DIST MAT CONST S/A DF FL 02
A12: FORNECEDORES | B12: NOVA DISTRIBUIDORA DE FERRAGENS LTDA
... A343: FORNECEDORES | B343: VCH - IMPORTADORA EXPORTADORA E DISTRIBUICAO DE P
